Workbook

Sheet 2009
E2: adicionl
A3: 1 | B3: Álvarez Ortega Ignacio | C3: socio | D3: 1
A4: 2 | B4: Antonio Ccente Jesús Maximo | C4: socio | D4: 1 | E4: 1
A5: 3 | B5: Artica De Cerrón Fortunata | C5: socio | D5: 1
A6: 4 | B6: Arzapalo De Pomachagua Brígida | C6: socio | D6: 1
A7: 6 | B7: Asto Ccente Victoria Máxima | C7: inquilina | D7: 1 | E7: 1
A8: 9 | B8: Barzola Bernuy Ayra | C8: socio | D8: 1 | E8: 1
A9: 12 | B9: Bonifacio Cachuay de Crisostomo Silveria Tomasa | C9: socio | D9: 1
A10: 13 | B10: Cáceres De Yupanqui María | C10: socio | D10: 1
A11: 14 | B11: Caja Santiago Vladimir Ernesto | C11: socio | D11: 1
A12: 15 | B12: Carhuallanqui Villanueva Martha | C12: socio | D12: 1
A13: 16 | B13: Carhuallanqui Villanueva Zenaida | C13: socio | D13: 1
A14: 17 | B14: Carlos Tocas Aida Lilia | C14: socio | D14: 1
A15: 19 | B15: Clemente Yauri Irene | C15: inquilina | D15: 1
A16: 23 | B16: Crúz Flores Carmen Cecilia | C16: socio | D16: 1
A17: 24 | B17: Cuicapusa Huarcaya Hilda | C17: socio | D17: 1
A18: 25 | B18: Cuicapusa Huarcaya Dorcas Isabel | C18: socio | D18: 1
A19: 28 | B19: Esteban Llacsa Clemencia Ana | C19: socio | D19: 1
A20: 29 | B20: Flores de Mandujano Magna Leonidas | C20: socio | D20: 1
... A22: 32 | B22: Garcia Acuña De Romero Margatira | C22: socio | D22: 1
A23: 33 | B23: García Coca Freddy Emerson | C23: socio | D23: 1 | E23: 1
A24: 36 | B24: Gutiérrez Viuda De Mendoza Rayda Alejandra | C24: socio | D24: 1
A25: 37 | B25: Hinostroza Rueda Aquiles Antonio | C25: socio | D25: 1
A26: 38 | B26: Huamaní Meza Elber | C26: inquilina | D26: 1 | E26: 1
A27: 39 | B27: Huamaní Meza Feliciana | C27: socio | D27: 1 | E27: 1
A28: 42 | B28: Jurado Quispe Marcelina | C28: socio | D28: 1
A29: 45 | B29: León De Hurtado Eugenia Entusa | C29: socio | D29: 1
A31: 49 | B31: Malpica Herrera Juliana | C31: socio | D31: 1
A33: 51 | B33: Marcelo de Cortez Udalia | C33: socio | D33: 1
A34: 53 | B34: Marticorena Benavente Yohana Mercedes | C34: socio | D34: 1
A35: 54 | B35: Mendoza Asto Ayda | C35: socio | D35: 1
A36: 58 | B36: Montes Viuda De Araujo Aleja | C36: socio | D36: 1
A37: 59 | B37: Orihuela Cevallos de Medina Elvira | C37: socio | D37: 1
A38: 63 | B38: Pocomucha Huaroc Silvio | C38: socio | D38: 1
A40: 66 | B40: Ramírez López Elsa Femicia | C40: socio | D40: 1
A41: 68 | B41: Ramos Condori Agripina | C41: socio | D41: 1
A42: 73 | B42: Rojas De Alvares Genoveva | C42: socio | D42: 1
A43: 75 | B43: Romero Rosas Ana Luisa | C43: socio | D43: 1 | E43: 1
A44: 77 | B44: Saravia De Condorí Honorata | C44: socio | D44: 1
A45: 81 | B45: Solís Solís Mónica Amanda | C45: socio | D45: 1 | E45: 1
...

Sheet 2010
A1: LISTA DE SOCIOS DEL MERCADO MICAELA BASTIDAS
A2: Nº | B2: APELLIDOS Y NOMBRES | C2: DNI | D2: PUESTOS | E2: DEUDA DE MANTENIMIENTO | F2: DEUDA DE FONDO ROTATORIO
A3: 88 | B3: Álvarez Ortega Ignacio | C3: Nº 20404573 | D3: TRABAJA SU ESPOSO | E3: DEUDA
A4: 85 | B4: Cóndor Alvaro Juana | D4: CERRADO
A5: 44 | B5: Amaro de Zurita Paulina | C5: Nº 40032417 | D5: ALQUILADO | E5: DEUDA
A6: 1 | B6: Antonio Ccente Jesus Maximo | C6: Nº 21269697 | D6: ACTIVO
A7: 45 | B7: Artica De Cerrón Fortunata | C7: Nº 19848218 | D7: ALQUILADO | E7: DEUDA
A8: 46 | B8: Arzapalo de Pomachagua Brígida | C8: Nº 21269150 | D8: ALQUILADO | E8: DEUDA
A9: 94 | B9: Arzapalo Yali Magloria | C9: Nº 20887419 | D9: TRABAJA SU HIJA | F9: DEUDA
A10: 47 | B10: Asto Ccente Victoria Máxima | C10: Nº 21269103 | D10: ALQUILADO | E10: DEUDA | F10: DEUDA
A11: 89 | B11: Asto De Mendoza Isidora | C11: Nº 19892783 | D11: TRABAJA SU HIJA | E11: DEUDA
A12: 90 | B12: Ayllón de Gomez Florencia | C12: Nº 19839679 | D12: TRABAJA SU HIJA | E12: DEUDA
A13: 86 | B13: Bacilio De Bravo Victoria | C13: Nº 20083468 | D13: PUESTO VENDIDO
A14: 2 | B14: Barzola Bernuy Ayra | C14: Nº 20093891 | D14: ACTIVO | E14: DEUDA | F14: DEUDA
A15: 3 | B15: Bastidas Ramírez Silvia Rosalía | C15: Nº 20057738 | D15: ACTIVO | E15: DEUDA
A16: 48 | B16: Bendezu Rodríguez Faustina Victoria | C16: Nº 19885733 | D16: ALQUILADO | E16: DEUDA
A17: 49 | B17: Bonifacio Cachuay Silveria Tomasa | C17: Nº 16132991 | D17: ALQUILADO | E17: DEUDA
A18: 50 | B18: Cáceres de Yupanqui María | C18: Nº 20089708 | D18: ALQUILADO
A19: 96 | B19: Caja Santiago Vladimir Hernesto | C19: Nº 20074730 | D19: TRABAJA SU MAMÁ | E19: DEUDA
A20: 51 | B20: Carhuallanqui Villanueva Martha | C20: Nº 19864790 | D20: ALQUILADO | E20: DEUDA | F20: DEUDA
A21: 4 | B21: Carhuallanqui Villanueva Zenaida | C21: Nº 19865513 | D21: ACTIVO | E21: DEUDA
A22: 5 | B22: Carlos Tocas Aida Lilia | C22: Nº 19845901 | D22: ACTIVO | E22: DEUDA
A23: 6 | B23: Chileno Huaynalaya Yolanda Ruth | C23: Nº 20055678 | D23: ACTIVO
A24: 52 | B24: Clemente Yauri Irene | C24: Nº 19972716 | D24: ALQUILADO
A25: 7 | B25: Cóndor Villalva Pricilio | C25: Nº 19813214 | D25: ACTIVO | E25: DEUDA
A26: 53 | B26: Condori Sedano Heddy | C26: Nº 41027349 | D26: ALQUILADO | E26: DEUDA | F26: DEUDA
A27: 54 | B27: Cruz Flores Carmen Cecilia | C27: Nº 20030915 | D27: ALQUILADO | E27: DEUDA | F27: DEUDA
A28: 8 | B28: Cuicapusa Huarcaya Hilda | C28: Nº 20052572 | D28: ACTIVO
A29: 9 | B29: De La Cruz Pampas Silvia Herlinda | C29: Nº 20405583 | D29: ACTIVO
A30: 10 | B30: Dionisio Valencia Ángel Teodoro | C30: Nº 20692636 | D30: ACTIVO | E30: DEUDA
A31: 74 | B31: Esteban Llacsa Clemencia Ana | C31: Nº 19836345 | D31: CERRADO | E31: DEUDA
A32: 75 | B32: Flores de Mandujano Magda Leonidas | C32: Nº 20697273 | D32: CERRADO
A33: 11 | B33: Flores Villaverde Gloria Adela | C33: Nº 19995621 | D33: ACTIVO
A34: 76 | B34: Galván Vílchez Luz Rebeca | C34: Nº 20097664 | D34: CERRADO | E34: DEUDA
A35: 12 | B35: Garcia Acuña Margatira | C35: Nº 21270275 | D35: ACTIVO | E35: DEUDA
A36: 13 | B36: García Coca Fredy Emerson | C36: Nº 20121038 | D36: ACTIVO
A37: 77 | B37: Gómez Romero Julia | C37: Nº 80151899 | D37: CERRADO | E37: DEUDA
A38: 78 | B38: Gongora Quispe Domola | C38: Nº | D38: CERRADO | E38: DEUDA
A39: 14 | B39: Gutiérrez De Mendoza Rayda Alejandra | C39: Nº 19802754 | D39: ACTIVO
A40: 55 | B40: Hinostroza Rueda Aquiles Antonio | C40: Nº 20692805 | D40: ALQUILADO
...

Sheet 2015
A1: Asociación De Pequeños Comerciantes Del Mercado De Abastos
A2: “Micaela Bastidas”
A4: CITACIÓN
A5: El Comité Electoral de la APCOMA –M.B. cita a todos los socios a una Asamblea General Extraordinaria a llevarse a cabo el día Viernes 13 de FEBRERO del 2015, primera citación 2:30 pm segunda y última citación 3:00 pm. En el local de nuestra asociación con el fin de tratar lo siguiente.
A10: AGENDA:
A11: Ø Aprobación del reglamento para las Elecciones Generales 2015.
A20: Nota: La asistencia es obligatoria de todos los socios titulares, no se aceptan subtitulares ni representantes, la inasistencia será multado con la suma de s/. 50.00 nuevos soles se suplica ser puntual.
B24: El Tambo, 04 de Febrero de 2015
B27: ASOCIACIÓN DE PEQUEÑOS COMERCIANTES DEL MERCADO DE ABASTOS
B28: “MICAELA BASTIDAS”
B29: PADRON DE SOCIOS ELECTORES
B30: 1 | C30: Artica De Cerrón Fortunata | D30: 19848218
B31: 2 | C31: Arzapalo De Pomachagua Brígida | D31: 21269150
B32: 3 | C32: Arzapalo Yali Magloria | D32: 20884719
B33: 4 | C33: Asto Ccente Victoria Máxima | D33: 21269103
B34: 5 | C34: Ayllón de Gomez Florencia | D34: 19839679
B35: 6 | C35: Bastidas Ramírez Silvia Rosalía | D35: 20057738
B36: 7 | C36: Bonifacio Cachuay de Crisostomo Silveria Tomasa | D36: 16132991
B37: 8 | C37: Cáceres De Yupanqui María | D37: 20089708
B38: 9 | C38: Carhuallanqui Villanueva Zenaida | D38: 19865513
B39: 10 | C39: Carlos Tocas Aida Lilia | D39: 19845901
B40: 11 | C40: Clemente Yauri Irene | D40: 19972716
B41: 12 | C41: Condor Alvaro Viuda De Flores Juana | D41: 19928540
... B98: 69 | C98: Zurita Amaro Ana Maria | D98: 20099171
B104: ASOCIACIÓN DE PEQUEÑOS COMERCIANTES DEL MERCADO DE ABASTOS
B105: “MICAELA BASTIDAS”
B106: SOCIOS NO EMPADRONADOS
B107: Nº | C107: APELLIDOS Y NOMBRES | D107: DNI | E107: FIRMA
B108: 1 | C108: Álvarez Ortega Ignacio | D108: 20404573
B109: 2 | C109: Antonio Ccente Jesús Maximo | D109: 21269697
B110: 3 | C110: Asto De Mendoza Isidora | D110: 19892783
B111: 4 | C111: Barzola Bernuy Ayra | D111: 20093891
B112: 5 | C112: Bendezú Rodríguez Faustina Victoria | D112: 19885733
B113: 6 | C113: Caja Santiago Vladimir Ernesto | D113: 20074730
B114: 7 | C114: Carhuallanqui Villanueva Martha | D114: 19864790
B115: 8 | C115: Chileno Huaynalaya Yolanda Ruth | D115: 20055678
B116: 9 | C116: Cóndor Villalva Precilio | D116: 19813214
B117: 10 | C117: Dionisio Valencia Ángel Teodoro | D117: 20692636
B118: 11 | C118: Esteban Llacsa Clemencia Ana | D118: 19836345
B119: 12 | C119: Huaringa Jines Ana Alida | D119: 20012197
...

Sheet 2019
A1: 1 | B1: Álvarez Ortega Ignacio
A2: 2 | B2: Antonio Ccente Jesús Maximo
A3: 3 | B3: Artica De Cerrón Fortunata
A4: 4 | B4: Arzapalo De Pomachagua Brígida
A5: 5 | B5: Arzapalo Yali Magloria
A6: 6 | B6: Asto Ccente Victoria Máxima
A7: 7 | B7: Asto De Mendoza Isidora
A8: 8 | B8: Ayllón de Gomez Florencia
A9: 9 | B9: Barzola Bernuy Ayra
A10: 10 | B10: Bastidas Ramírez Silvia Rosalía
A11: 11 | B11: Bendezú Rodríguez Faustina Victoria
A12: 12 | B12: Bonifacio Cachuay de Crisostomo Silveria Tomasa
... A108: 107 | B108: Urbano Vilchez Alvaro

Sheet 2020
A1: Nº | B1: APELLIDOS Y NOMBRES | C1: DNI | E1: Nº | F1: APELLIDOS Y NOMBRES | G1: DNI
A2: 1 | B2: ALDERETE VELASQUEZ TABITA YNES | C2: 20119761 | E2: 10 | F2: ARZAPALO YALI MAGLORIA | G2: 20884719
A3: 2 | B3: ALVAREZ CRISTOBAL LIZBETH GIANINA | C3: 70395045 | E3: 2 | F3: BASTIDAS RAMÍREZ SILVIA ROSALÍA | G3: 20057738
A4: 3 | B4: ARIAS GALVAN JHONATAN | C4: 46386473 | E4: 3 | F4: DE LA CRUZ PAMPAS SILVIA HERLINDA | G4: 20405583
A5: 4 | B5: ARTICA DE CERRÓN FORTUNATA | C5: 19848218 | E5: 4 | F5: DIONISIO VALENCIA ÁNGEL TEODORO | G5: 20692636
A6: 5 | B6: ARZAPALO YALI MAGLORIA | C6: 20884719 | E6: 5 | F6: MARTICORENA BENAVENTE YOHANA MERCEDES | G6: 20670271
A7: 6 | B7: ASTO CCENTE VICTORIA MÁXIMA | C7: 21269103 | E7: 6 | F7: RAFAEL PECHO TEOFILA JUSTA | G7: 19997172
A8: 7 | B8: ASTO DE MENDOZA ISIDORA | C8: 19892783 | E8: 7 | F8: VARGAS LAURENTE YOLANDA JUANA | G8: 20100904
A9: 8 | B9: AYLLÓN SERVA FLORENCIA | C9: 19839679
A10: 9 | B10: BARZOLA BERNUY AYRA | C10: 20093891
A11: 10 | B11: BASTIDAS RAMÍREZ SILVIA ROSALÍA | C11: 20057738
A12: 11 | B12: MENDOZA BENDEZU MARISOL MAKRINA | C12: 40078108
A13: 12 | B13: BONIFACIO CACHUAY , SILVERIA TOMASA | C13: 16132991
A14: 13 | B14: CARLOS TOCAS AIDA LILIA | C14: 19845901
A15: 14 | B15: CARRASCO ROJAS DE TIZA EDITH | C15: 41671307
A16: 15 | B16: CERVANTES CHILENO LESLY EVELYN | C16: 77805419
A17: 16 | B17: CHILENO HUAYNALAYA YOLANDA RUTH | C17: 20055678
A18: 17 | B18: CHILQUILLO MACHUCA DONY EVELINA | C18: 20127656
A19: 18 | B19: CÓNDOR VILLALVA PRICILIO | C19: 19813214
A20: 19 | B20: CONDORÍ SEDANO HEDDY | C20: 41027349
... A98: 97 | B98: ZURITA AMARO ANA MARIA | C98: 20099171
B99: RIOS MERCADO ANA MARIA | C99: 46184653
B100: ARTEAGA YURIVILCA MARITZA LUSMILA | C100: 40153193

Sheet 2022
A1: Asociación De Pequeños Comerciantes Del Mercado De Abastos
A2: “Micaela Bastidas”
A4: CITACIÓN
A5: El Comité Electoral de la APCOMA –M.B. cita a todos los socios a una Asamblea General Extraordinaria a llevarse a cabo el día Viernes 13 de FEBRERO del 2015, primera citación 2:30 pm segunda y última citación 3:00 pm. En el local de nuestra asociación con el fin de tratar lo siguiente.
A10: AGENDA:
A11: Ø Aprobación del reglamento para las Elecciones Generales 2015.
A20: Nota: La asistencia es obligatoria de todos los socios titulares, no se aceptan subtitulares ni representantes, la inasistencia será multado con la suma de s/. 50.00 nuevos soles se suplica ser puntual.
B24: El Tambo, 04 de Febrero de 2015
B27: ASOCIACIÓN DE PEQUEÑOS COMERCIANTES DEL MERCADO DE ABASTOS
B28: “MICAELA BASTIDAS”
B29: PADRON DE SOCIOS ASISTENTES A LA ASAMBLEA GENERAL EXTRAORDINARIA 04- 02-2022
B31: Nº | C31: APELLIDOS Y NOMBRES | D31: DNI | E31: FIRMA | F31: HELLA
B32: 1 | C32: ALDERETE VELASQUEZ TABITA YNES | D32: 20119761
B33: 2 | C33: ALVAREZ CRISTOBAL LIZBETH GIANINA | D33: 70395045
B34: 3 | C34: Arias Galvan Jhonatan | D34: 46386473
B35: 4 | C35: Artica De Cerrón Fortunata | D35: 19848218
B36: 5 | C36: Arzapalo Yali Magloria | D36: 20884719
B37: 6 | C37: Asto Ccente Victoria Máxima | D37: 21269103
B38: 7 | C38: Asto De Mendoza Isidora | D38: 19892783
B39: 8 | C39: Ayllón Serva Florencia | D39: 19839679
B40: 9 | C40: Barzola Bernuy Ayra | D40: 20093891
B41: 10 | C41: Bastidas Ramírez Silvia Rosalía | D41: 20057738
B42: 11 | C42: Bejarano Lazaro Carmen | D42: 20077729
B43: 12 | C43: Bendezú Rodríguez Faustina Victoria | D43: 19885733
... B119: 88 | C119: Zurita Amaro Ana Maria | D119: 20099171
B120: SOCIOS EN PRUEBA
B121: Nº | C121: APELLIDOS Y NOMBRES | D121: DNI | E121: FIRMA | F121: HELLA
B122: 89 | C122: Medina Orihuela Gabriela Jhoselin | D122: 70041842
B123: 90 | C123: Yupanqui Ramos Marcos | D123: 20082323
B124: 91 | C124: CCAPA MALDONADO KIMBERLY PAMELA | D124: 71740905
B125: 92 | C125: CERVANTES CHILENO LESLY EVELYN | D125: 77805419
B126: 93 | C126: CHILQUILLO MACHUCA DONY EVELINA | D126: 20127656
B127: 94 | C127: CRISPIN TAYPE LEOGIVILDO | D127: 45472119
B128: 95 | C128: MENDOZA ASTO CARMEN KARINA | D128: 40061246
B129: 96 | C129: MORALES LAZO DELIA | D129: 43777541
B130: 97 | C130: ÑAUPARI TICSE CARLOS YOEL | D130: 44512621
B131: 98 | C131: PIÑAS ORELLANA NILDA | D131: 45736330
B132: 99 | C132: QUISPE RETIZ ZENAIDA | D132: 20415566
B133: 100 | C133: RAMOS CANGAHUALA JENY | D133: 40707284
... B140: 107 | C140: VILLANUEVA FERNANDEZ AMELIA CELESTINA | D140: 41012742

Sheet elecciones 2022
A1: Asociación De Pequeños Comerciantes Del Mercado De Abastos
A2: “Micaela Bastidas”
A4: CITACIÓN
A5: El Comité Electoral de la APCOMA –M.B. cita a todos los socios a una Asamblea General Extraordinaria a llevarse a cabo el día Viernes 13 de FEBRERO del 2015, primera citación 2:30 pm segunda y última citación 3:00 pm. En el local de nuestra asociación con el fin de tratar lo siguiente.
A10: AGENDA:
A11: Ø Aprobación del reglamento para las Elecciones Generales 2015.
A20: Nota: La asistencia es obligatoria de todos los socios titulares, no se aceptan subtitulares ni representantes, la inasistencia será multado con la suma de s/. 50.00 nuevos soles se suplica ser puntual.
B24: El Tambo, 04 de Febrero de 2015
B27: ASOCIACIÓN DE PEQUEÑOS COMERCIANTES DEL MERCADO DE ABASTOS
B28: “MICAELA BASTIDAS”
B29: PADRON DE SOCIOS ASISTENTES A LA ASAMBLEA GENERAL EXTRAORDINARIA 04- 02-2022
B31: Nº | C31: APELLIDOS Y NOMBRES | D31: DNI | E31: FIRMA | F31: HELLA
B32: 1 | C32: ALDERETE VELASQUEZ TABITA YNES | D32: 20119761
B33: 2 | C33: ALVAREZ CRISTOBAL LIZBETH GIANINA | D33: 70395045
B34: 3 | C34: Arias Galvan Jhonatan | D34: 46386473
B35: 4 | C35: Artica De Cerrón Fortunata | D35: 19848218
B36: 5 | C36: Arzapalo Yali Magloria | D36: 20884719
B37: 6 | C37: Asto Ccente Victoria Máxima | D37: 21269103
B38: 7 | C38: Asto De Mendoza Isidora | D38: 19892783
B39: 8 | C39: Ayllón Serva Florencia | D39: 19839679
B40: 9 | C40: Barzola Bernuy Ayra | D40: 20093891
B41: 10 | C41: Bastidas Ramírez Silvia Rosalía | D41: 20057738
B42: 11 | C42: Bejarano Lazaro Carmen | D42: 20077729
B43: 12 | C43: Bendezú Rodríguez Faustina Victoria | D43: 19885733
... B119: 88 | C119: Zurita Amaro Ana Maria | D119: 20099171
B120: SOCIOS EN PRUEBA
B121: Nº | C121: APELLIDOS Y NOMBRES | D121: DNI | E121: FIRMA | F121: HELLA
B122: 89 | C122: ARTEAGA YURIVILCA MARITZA LUZMILA | D122: 40153193
B123: 90 | C123: BALTAZAR AQUINO HEYDI | D123: 45247844
B124: 91 | C124: CCAPA MALDONADO KIMBERLY PAMELA | D124: 71740905
B125: 92 | C125: CERVANTES CHILENO LESLY EVELYN | D125: 77805419
B126: 93 | C126: CHILQUILLO MACHUCA DONY EVELINA | D126: 20127656
B127: 94 | C127: CRISPIN TAYPE LEOGIVILDO | D127: 45472119
B128: 95 | C128: MENDOZA ASTO CARMEN KARINA | D128: 40061246
B129: 96 | C129: MORALES LAZO DELIA | D129: 43777541
B130: 97 | C130: ÑAUPARI TICSE CARLOS YOEL | D130: 44512621
B131: 98 | C131: PIÑAS ORELLANA NILDA | D131: 45736330
B132: 99 | C132: QUISPE RETIZ ZENAIDA | D132: 20415566
B133: 100 | C133: RAMOS CANGAHUALA JENY | D133: 40707284
... B140: 107 | C140: VILLANUEVA FERNANDEZ AMELIA CELESTINA | D140: 41012742

Sheet 2024
B1: Nº | C1: APELLIDOS Y NOMBRES | D1: APELLIDOS Y NOMBRES | E1: DNI | F1: FIRMA | G1: HUELLA | H1: CONDICION
B2: 1 | C2: ALDERETE VELASQUEZ TABITA YNES | D2: =UPPER(C2) -> ALDERETE VELASQUEZ TABITA YNES | E2: 20119761 | H2: SOCIO
B3: 2 | C3: ALVAREZ CRISTOBAL LIZBETH GIANINA | D3: =UPPER(C3) -> ALVAREZ CRISTOBAL LIZBETH GIANINA | E3: 70395045 | H3: SOCIO
B4: 3 | C4: Arias Galvan Jhonatan | D4: =UPPER(C4) -> ARIAS GALVAN JHONATAN | E4: 46386473 | H4: SOCIO
B5: 4 | C5: ARTEAGA YURIVILCA MARITZA LUZMILA | D5: =UPPER(C5) -> ARTEAGA YURIVILCA MARITZA LUZMILA | E5: 40153193 | H5: SOCIO
B6: 5 | C6: Artica De Cerrón Fortunata | D6: =UPPER(C6) -> ARTICA DE CERRÓN FORTUNATA | E6: 19848218 | H6: SOCIO
B7: 6 | C7: Arzapalo Yali Magloria | D7: =UPPER(C7) -> ARZAPALO YALI MAGLORIA | E7: 20884719 | H7: SOCIO
B8: 7 | C8: Asto Ccente Victoria Máxima | D8: =UPPER(C8) -> ASTO CCENTE VICTORIA MÁXIMA | E8: 21269103 | H8: SOCIO
B9: 8 | C9: Asto De Mendoza Isidora | D9: =UPPER(C9) -> ASTO DE MENDOZA ISIDORA | E9: 19892783 | H9: SOCIO
B10: 9 | C10: Ayllón Serva Florencia | D10: =UPPER(C10) -> AYLLÓN SERVA FLORENCIA | E10: 19839679 | H10: SOCIO
B11: 10 | C11: BALTAZAR AQUINO HEYDI | D11: =UPPER(C11) -> BALTAZAR AQUINO HEYDI | E11: 45247844 | H11: SOCIO
B12: 11 | C12: Barzola Bernuy Ayra | D12: =UPPER(C12) -> BARZOLA BERNUY AYRA | E12: 20093891 | H12: SOCIO
B13: 12 | C13: Bastidas Ramírez Silvia Rosalía | D13: =UPPER(C13) -> BASTIDAS RAMÍREZ SILVIA ROSALÍA | E13: 20057738 | H13: SOCIO
... B89: 87 | C89: Ticllacuri Huamaní Luz Matilde | D89: =UPPER(C89) -> TICLLACURI HUAMANÍ LUZ MATILDE | E89: 21269375 | H89: SOCIO
B90: 88 | C90: Ñaupari Capcha Oscar Raul | D90: =UPPER(C90) -> ÑAUPARI CAPCHA OSCAR RAUL | H90: SOCIO
B91: 89 | C91: Trinidad Alavarado Pilar Teofila | D91: =UPPER(C91) -> TRINIDAD ALAVARADO PILAR TEOFILA | E91: 4071342 | H91: SOCIO
B92: 90 | C92: Urbano Martínez Herlinda | D92: =UPPER(C92) -> URBANO MARTÍNEZ HERLINDA | E92: 20024426 | H92: SOCIO
B93: 91 | C93: URBANO VILCHEZ ALVARO | D93: =UPPER(C93) -> URBANO VILCHEZ ALVARO | E93: 70231168 | H93: SOCIO
B94: 92 | C94: Vargas Laurente Yolanda Juana | D94: =UPPER(C94) -> VARGAS LAURENTE YOLANDA JUANA | E94: 20100904 | H94: SOCIO
B95: 93 | C95: Vilchez Aguilar Hermelinda | D95: =UPPER(C95) -> VILCHEZ AGUILAR HERMELINDA | E95: 19851711 | H95: SOCIO
B96: 94 | C96: Vilchez Pérez Rosario Lúz | D96: =UPPER(C96) -> VILCHEZ PÉREZ ROSARIO LÚZ | E96: 20026869 | H96: SOCIO
B97: 95 | C97: VILLANUEVA FERNANDEZ AMELIA CELESTINA | D97: =UPPER(C97) -> VILLANUEVA FERNANDEZ AMELIA CELESTINA | E97: 41012742 | H97: SOCIO
B98: 96 | C98: Yaringaño Espinoza Tobías Donato | D98: =UPPER(C98) -> YARINGAÑO ESPINOZA TOBÍAS DONATO | E98: 20652545 | H98: SOCIO
B99: 97 | C99: Yupanqui Romero Marcos | D99: =UPPER(C99) -> YUPANQUI ROMERO MARCOS | E99: 20082323 | H99: SOCIO
B100: 98 | C100: Zuasnabar Cunyas Fernando Fredy | D100: =UPPER(C100) -> ZUASNABAR CUNYAS FERNANDO FREDY | E100: 41190570 | H100: SOCIO
B101: 99 | C101: Zurita Amaro Ana Maria | D101: =UPPER(C101) -> ZURITA AMARO ANA MARIA | E101: 20099171 | H101: SOCIO
B102: 100 | C102: MATOS MONDARGO JOSE CARLOS | D102: =UPPER(C102) -> MATOS MONDARGO JOSE CARLOS | E102: 48407208 | H102: SOCIO
... B109: 107 | C109: CASTILLÓN SIUCE MAGALY | D109: =UPPER(C109) -> CASTILLÓN SIUCE MAGALY | E109: 42241717 | H109: SOCIO
D110: =+PROPER(C110)
D111: =+PROPER(C111)
D112: =+PROPER(C112)
D113: =+PROPER(C113)
D114: =+PROPER(C114)
D115: =+PROPER(C115)
D116: =+PROPER(C116)
D117: =+PROPER(C117)
D118: =+PROPER(C118)
D119: =+PROPER(C119)
D120: =+PROPER(C120)
D121: =+PROPER(C121)
...

Sheet ELECCIONES-2026 (2)
A1: PADRON DE SOCIOS 2026 ASOCIACION DE PEQUEÑOS COMERCIANTES DEL MERCADO DE ABASTOS MICAELA BASTIDAS
A2: Nº | B2: APELLIDOS Y NOMBRES | C2: DNI | D2: CONDICION | E2: FIRMA | F2: HUELLA
A3: 1 | B3: ='2024'!D2 -> ALDERETE VELASQUEZ TABITA YNES | C3: 20119761 | D3: SOCIO
A4: 2 | B4: ='2024'!D4 -> ARIAS GALVAN JHONATAN | C4: 46386473 | D4: SOCIO
A5: 3 | B5: ='2024'!D6 -> ARTICA DE CERRÓN FORTUNATA | C5: 19848218 | D5: SOCIO
A6: 4 | B6: ='2024'!D7 -> ARZAPALO YALI MAGLORIA | C6: 20884719 | D6: SOCIO
A7: 5 | B7: ='2024'!D8 -> ASTO CCENTE VICTORIA MÁXIMA | C7: 21269103 | D7: SOCIO
A8: 6 | B8: ='2024'!D9 -> ASTO DE MENDOZA ISIDORA | C8: 19892783 | D8: SOCIO
A9: 7 | B9: ='2024'!D10 -> AYLLÓN SERVA FLORENCIA | C9: 19839679 | D9: SOCIO
A10: 8 | B10: ='2024'!D13 -> BASTIDAS RAMÍREZ SILVIA ROSALÍA | C10: 42781068 | D10: SOCIO
A11: 9 | B11: ='2024'!D12 -> BARZOLA BERNUY AYRA | C11: 20093891 | D11: SOCIO
A12: 10 | B12: ='2024'!D13 -> BASTIDAS RAMÍREZ SILVIA ROSALÍA | C12: 20057738 | D12: SOCIO
A13: 11 | B13: ='2024'!D14 -> BONIFACIO CACHUAY , SILVERIA TOMASA | C13: 16132991 | D13: SOCIO
A14: 12 | B14: ='2024'!D15 -> CARLOS TOCAS AIDA LILIA | C14: 19845901 | D14: SOCIO
A15: 13 | B15: ='2024'!D16 -> CARRASCO ROJAS DE TIZA EDITH | C15: 41671307 | D15: SOCIO
A16: 14 | B16: ='2024'!D17 -> CCAPA MALDONADO KIMBERLY PAMELA | C16: 71740903 | D16: SOCIO
A17: 15 | B17: ='2024'!D18 -> CASTILLÓN SIUCE MAGALY | C17: 42241717 | D17: SOCIO
A18: 16 | B18: ='2024'!D19 -> CERVANTES CHILENO LESLY EVELYN | C18: 77805419 | D18: SOCIO
A19: 17 | B19: ='2024'!D20 -> CHILENO HUAYNALAYA YOLANDA RUTH | C19: 20055678 | D19: SOCIO
A20: 18 | B20: ='2024'!D21 -> CHILQUILLO MACHUCA DONY EVELINA | C20: 20127656 | D20: SOCIO
A21: 19 | B21: ='2024'!D22 -> CÓNDOR VILLALVA PRICILIO | C21: 19813214 | D21: SOCIO
A22: 20 | B22: ='2024'!D23 -> CONDORÍ SEDANO HEDDY | C22: 41027349 | D22: SOCIO
... A33: 31 | B33: ='2024'!D34 -> GARCÍA COCA FREDDY EMERSON | C33: 20122038 | D33: SOCIO
A34: 32 | B34: ='2024'!D37 -> GUTIÉRREZ VIUDA DE MENDOZA RAYDA ALEJANDRA | C34: 19802754 | D34: SOCIO
A35: 33 | B35: ='2024'!D38 -> HINOSTROZA RUEDA AQUILES ANTONIO | C35: 20692805 | D35: SOCIO
A36: 34 | B36: ='2024'!D39 -> HUAMANÍ MEZA ELBER | C36: 20028524 | D36: SOCIO
A37: 35 | B37: ='2024'!D40 -> HUAMANÍ MEZA FELICIANA | C37: 20051895 | D37: SOCIO
A38: 36 | B38: ='2024'!D41 -> HUARINGA JINES ANA ALIDA | C38: 20012197 | D38: SOCIO
A39: 37 | B39: ='2024'!D42 -> JURADO QUISPE MARCELINA | C39: 20079126 | D39: SOCIO
A40: 38 | B40: ='2024'!D43 -> LAURA FLORES YOVANA ERNESTINA | C40: 40350496 | D40: SOCIO
A41: 39 | B41: ='2024'!D44 -> LAZO REYES MARIBEL FÁTIMA | C41: 19801537 | D41: SOCIO
A42: 40 | B42: ='2024'!D45 -> LAZO REYES RAUL | C42: 19843280 | D42: SOCIO
A43: 41 | B43: ='2024'!D46 -> LEÓN DE HURTADO EUGENIA ENTUSA | C43: 21279978 | D43: SOCIO
A44: 42 | B44: ='2024'!D47 -> LÓPEZ HUAMAN ROGELIO IGNACIO | C44: 19883460 | D44: SOCIO
A45: 43 | B45: ='2024'!D48 -> LOZANO TORRES CAMILA | C45: 19994775 | D45: SOCIO
... A49: 47 | B49: ='2024'!D52 -> MARTICORENA BENAVENTE YOHANA MERCEDES | C49: 20670271 | D49: SOCIO
A50: 48 | B50: MATOS MONDARGO JOSE CARLOS | C50: 48407208 | D50: SOCIO
A51: 49 | B51: ='2024'!D54 -> MEDINA ORIHUELA GABRIELA JHOSELIN | C51: 70041842 | D51: SOCIO
A52: 50 | B52: ='2024'!D56 -> MENDOZA ASTO CARMEN KARINA | C52: 40061246 | D52: SOCIO
A53: 51 | B53: MENDOZA BENDEZU MARISOL MAKRINA | C53: 40078108 | D53: SOCIO
...

Sheet ELECCIONES-2026
A1: PADRON DE SOCIOS 2026 ASOCIACION DE PEQUEÑOS COMERCIANTES DEL MERCADO DE ABASTOS MICAELA BASTIDAS
A2: Nº | B2: APELLIDOS Y NOMBRES | C2: DNI | D2: CONDICION | E2: FIRMA | F2: HUELLA
A3: 1 | B3: ='2024'!D2 -> ALDERETE VELASQUEZ TABITA YNES | C3: 20119761 | D3: SOCIO
A4: 2 | B4: ='2024'!D3 -> ALVAREZ CRISTOBAL LIZBETH GIANINA | C4: 70395045 | D4: SOCIO
A5: 3 | B5: ='2024'!D4 -> ARIAS GALVAN JHONATAN | C5: 46386473 | D5: SOCIO
A6: 4 | B6: ='2024'!D5 -> ARTEAGA YURIVILCA MARITZA LUZMILA | C6: 40153193 | D6: SOCIO
A7: 5 | B7: ='2024'!D6 -> ARTICA DE CERRÓN FORTUNATA | C7: 19848218 | D7: SOCIO
A8: 6 | B8: ='2024'!D7 -> ARZAPALO YALI MAGLORIA | C8: 20884719 | D8: SOCIO
A9: 7 | B9: ='2024'!D8 -> ASTO CCENTE VICTORIA MÁXIMA | C9: 21269103 | D9: SOCIO
A10: 8 | B10: ='2024'!D9 -> ASTO DE MENDOZA ISIDORA | C10: 19892783 | D10: SOCIO
A11: 9 | B11: ='2024'!D10 -> AYLLÓN SERVA FLORENCIA | C11: 19839679 | D11: SOCIO
A12: 10 | B12: BARAHONA MIGUEL ELIZAMA HERLINDA | C12: 42781068 | D12: SOCIO
A13: 11 | B13: ='2024'!D12 -> BARZOLA BERNUY AYRA | C13: 20093891 | D13: SOCIO
A14: 12 | B14: ='2024'!D13 -> BASTIDAS RAMÍREZ SILVIA ROSALÍA | C14: 20057738 | D14: SOCIO
A15: 13 | B15: ='2024'!D14 -> BONIFACIO CACHUAY , SILVERIA TOMASA | C15: 16132991 | D15: SOCIO
A16: 14 | B16: ='2024'!D15 -> CARLOS TOCAS AIDA LILIA | C16: 19845901 | D16: SOCIO
A17: 15 | B17: ='2024'!D16 -> CARRASCO ROJAS DE TIZA EDITH | C17: 41671307 | D17: SOCIO
A18: 16 | B18: ='2024'!D17 -> CCAPA MALDONADO KIMBERLY PAMELA | C18: 71740903 | D18: SOCIO
A19: 17 | B19: ='2024'!D18 -> CASTILLÓN SIUCE MAGALY | C19: 42241717 | D19: SOCIO
A20: 18 | B20: ='2024'!D19 -> CERVANTES CHILENO LESLY EVELYN | C20: 77805419 | D20: SOCIO
A21: 19 | B21: ='2024'!D20 -> CHILENO HUAYNALAYA YOLANDA RUTH | C21: 20055678 | D21: SOCIO
A22: 20 | B22: ='2024'!D21 -> CHILQUILLO MACHUCA DONY EVELINA | C22: 20127656 | D22: SOCIO
A23: 21 | B23: ='2024'!D22 -> CÓNDOR VILLALVA PRICILIO | C23: 19813214 | D23: SOCIO
A24: 22 | B24: ='2024'!D23 -> CONDORÍ SEDANO HEDDY | C24: 41027349 | D24: SOCIO
... A42: 40 | B42: ='2024'!D41 -> HUARINGA JINES ANA ALIDA | C42: 20012197 | D42: SOCIO
A43: 41 | B43: HURTADO ROMERO HEYDDY IRIS | C43: 44889363 | D43: SOCIO
A44: 42 | B44: ='2024'!D42 -> JURADO QUISPE MARCELINA | C44: 20079126 | D44: SOCIO
A45: 43 | B45: ='2024'!D43 -> LAURA FLORES YOVANA ERNESTINA | C45: 40350496 | D45: SOCIO
A46: 44 | B46: ='2024'!D44 -> LAZO REYES MARIBEL FÁTIMA | C46: 19801537 | D46: SOCIO
A47: 45 | B47: ='2024'!D45 -> LAZO REYES RAUL | C47: 19843280 | D47: SOCIO
A48: 46 | B48: ='2024'!D46 -> LEÓN DE HURTADO EUGENIA ENTUSA | C48: 21279978 | D48: SOCIO
A49: 47 | B49: ='2024'!D47 -> LÓPEZ HUAMAN ROGELIO IGNACIO | C49: 19883460 | D49: SOCIO
A50: 48 | B50: ='2024'!D48 -> LOZANO TORRES CAMILA | C50: 19994775 | D50: SOCIO
A51: 49 | B51: ='2024'!D49 -> LUIS GALLARDO ELOY MARIANO | C51: 20087969 | D51: SOCIO
A52: 50 | B52: ='2024'!D50 -> LUIS MARTICORENA AUSSY GARDENIA | C52: 20073695 | D52: SOCIO
A53: 51 | B53: ='2024'!D51 -> MARCELO DE CORTEZ UDALIA | C53: 19993410 | D53: SOCIO
A54: 52 | B54: ='2024'!D52 -> MARTICORENA BENAVENTE YOHANA MERCEDES | C54: 20670271 | D54: SOCIO
A55: 53 | B55: MATOS MONDARGO JOSE CARLOS | C55: 48407208 | D55: SOCIO
A56: 54 | B56: ='2024'!D53 -> MATOS VILLAZANA SONIA | C56: 20042885 | D56: SOCIO
A57: 55 | B57: ='2024'!D54 -> MEDINA ORIHUELA GABRIELA JHOSELIN | C57: 70041842 | D57: SOCIO
...

Sheet ELECCIONES-2025
A1: PADRON DE SOCIOS 2025 ASOCIACION DE PEQUEÑOS COMERCIANTES DEL MERCADO DE ABASTOS MICAELA BASTIDAS
A2: Nº | B2: APELLIDOS Y NOMBRES | C2: DNI | D2: CONDICION | E2: FIRMA | F2: HUELLA
A3: 1 | B3: ='2024'!D2 -> ALDERETE VELASQUEZ TABITA YNES | C3: 20119761 | D3: SOCIO
A4: 2 | B4: ='2024'!D3 -> ALVAREZ CRISTOBAL LIZBETH GIANINA | C4: 70395045 | D4: SOCIO
A5: 3 | B5: ='2024'!D4 -> ARIAS GALVAN JHONATAN | C5: 46386473 | D5: SOCIO
A6: 4 | B6: ='2024'!D5 -> ARTEAGA YURIVILCA MARITZA LUZMILA | C6: 40153193 | D6: SOCIO
A7: 5 | B7: ='2024'!D6 -> ARTICA DE CERRÓN FORTUNATA | C7: 19848218 | D7: SOCIO
A8: 6 | B8: ='2024'!D7 -> ARZAPALO YALI MAGLORIA | C8: 20884719 | D8: SOCIO
A9: 7 | B9: ='2024'!D8 -> ASTO CCENTE VICTORIA MÁXIMA | C9: 21269103 | D9: SOCIO
A10: 8 | B10: ='2024'!D9 -> ASTO DE MENDOZA ISIDORA | C10: 19892783 | D10: SOCIO
A11: 9 | B11: ='2024'!D10 -> AYLLÓN SERVA FLORENCIA | C11: 19839679 | D11: SOCIO
A12: 10 | B12: ='2024'!D11 -> BALTAZAR AQUINO HEYDI | C12: 45247844 | D12: SOCIO
A13: 11 | B13: ='2024'!D12 -> BARZOLA BERNUY AYRA | C13: 20093891 | D13: SOCIO
A14: 12 | B14: ='2024'!D13 -> BASTIDAS RAMÍREZ SILVIA ROSALÍA | C14: 20057738 | D14: SOCIO
... A53: 51 | B53: ='2024'!D52 -> MARTICORENA BENAVENTE YOHANA MERCEDES | C53: 20670271 | D53: SOCIO
A54: 52 | B54: MATOS MONDARGO JOSE CARLOS | C54: 48407208 | D54: SOCIO
A55: 53 | B55: ='2024'!D53 -> MATOS VILLAZANA SONIA | C55: 20042885 | D55: SOCIO
A56: 54 | B56: ='2024'!D54 -> MEDINA ORIHUELA GABRIELA JHOSELIN | C56: 70041842 | D56: SOCIO
A57: 55 | B57: ='2024'!D55 -> MENDOZA ASTO AYDA | C57: 20047549 | D57: SOCIO
A58: 56 | B58: ='2024'!D56 -> MENDOZA ASTO CARMEN KARINA | C58: 40061246 | D58: SOCIO
A59: 57 | B59: MENDOZA BENDEZU MARISOL MAKRINA | C59: 40078108 | D59: SOCIO
A60: 58 | B60: ='2024'!D57 -> MEZA SCHWARTZ GALINA VICENTA | C60: 20040608 | D60: SOCIO
A61: 59 | B61: ='2024'!D58 -> MOLINA DE GASPAR TEODOSIA | C61: 19881249 | D61: SOCIO
A62: 60 | B62: ='2024'!D59 -> MONTES DE ARAUJO ALEJA | C62: 19953627 | D62: SOCIO
A63: 61 | B63: ='2024'!D60 -> MORALES LAZO DELIA | C63: 43777541 | D63: SOCIO
A64: 62 | B64: ÑAUPARI CAPCHA OSCAR RAUL | C64: 20682664 | D64: SOCIO
A65: 63 | B65: ='2024'!D61 -> ÑAUPARI TICSE CARLOS YOEL | C65: 44512621 | D65: SOCIO
A66: 64 | B66: ='2024'!D62 -> ORIHUELA DE LAPA BEATRIZ | C66: 20083528 | D66: SOCIO
A67: 65 | B67: ='2024'!D63 -> PEREZ VIUDA DE QUISPE BERTHA LAISA | C67: 19902222 | D67: SOCIO
A68: 66 | B68: ='2024'!D65 -> POCOMUCHA HUAROC SILVIO | C68: 21246684 | D68: SOCIO
A69: 67 | B69: ='2024'!D66 -> QUINTANA PEÑA OLINDA YOLANDA DONATA | C69: 19914822 | D69: SOCIO
A70: 68 | B70: ='2024'!D67 -> QUISPE RETIZ ZENAIDA | C70: 20415566 | D70: SOCIO
A71: 69 | B71: ='2024'!D68 -> RAFAEL PECHO TEOFILA JUSTA | C71: 19997172 | D71: SOCIO
A72: 70 | B72: ='2024'!D69 -> RAMÍREZ LÓPEZ ELSA FEMICIA | C72: 20665423 | D72: SOCIO
A73: 71 | B73: ='2024'!D70 -> RAMIREZ RIVERA JOSEFINA ALEJANDRA | C73: 19968871 | D73: SOCIO
A74: 72 | B74: ='2024'!D71 -> RAMOS CANGAHUALA JENY | C74: 40707284 | D74: SOCIO
A75: 73 | B75: ='2024'!D72 -> RAMOS CONDORI AGRIPINA | C75: 23266009 | D75: SOCIO
A76: 74 | B76: ='2024'!D73 -> REQUIZ ROBLES ALEJANDRO | C76: 20082972 | D76: SOCIO
A77: 75 | B77: ='2024'!D74 -> REQUIZ SOTO YIYE | C77: 40802806 | D77: SOCIO
A78: 76 | B78: ='2024'!D75 -> RIOS MERCADO ANA MARIA | C78: 46184653 | D78: SOCIO
...

Sheet 2025
A1: Nº | B1: APELLIDOS Y NOMBRES | C1: APELLIDOS Y NOMBRES | D1: DNI | E1: FIRMA | F1: GIRO | G1: CONDICION | H1: TELEFONO
A2: 1 | B2: ALDERETE VELASQUEZ TABITA YNES | C2: =UPPER(B2) -> ALDERETE VELASQUEZ TABITA YNES | D2: 20119761 | F2: JUGOS | G2: SOCIO
A3: 2 | B3: ALVAREZ CRISTOBAL LIZBETH GIANINA | C3: =UPPER(B3) -> ALVAREZ CRISTOBAL LIZBETH GIANINA | D3: 70395045 | F3: COMIDA | G3: SOCIO
A4: 3 | B4: Arias Galvan Jhonatan | C4: =UPPER(B4) -> ARIAS GALVAN JHONATAN | D4: 46386473 | F4: BAZAR | G4: SOCIO
A5: 4 | B5: ARTEAGA YURIVILCA MARITZA LUZMILA | C5: =UPPER(B5) -> ARTEAGA YURIVILCA MARITZA LUZMILA | D5: 40153193 | F5: TALLER | G5: SOCIO
A6: 5 | B6: Artica De Cerrón Fortunata | C6: =UPPER(B6) -> ARTICA DE CERRÓN FORTUNATA | D6: 19848218 | F6: PAPA | G6: SOCIO
A7: 6 | B7: Arzapalo Yali Magloria | C7: =UPPER(B7) -> ARZAPALO YALI MAGLORIA | D7: 20884719 | F7: CONFITERIA | G7: SOCIO
A8: 7 | B8: Asto Ccente Victoria Máxima | C8: =UPPER(B8) -> ASTO CCENTE VICTORIA MÁXIMA | D8: 21269103 | F8: COMIDA | G8: SOCIO
A9: 8 | B9: Asto De Mendoza Isidora | C9: =UPPER(B9) -> ASTO DE MENDOZA ISIDORA | D9: 19892783 | F9: VERDURA | G9: SOCIO
A10: 9 | B10: Ayllón Serva Florencia | C10: =UPPER(B10) -> AYLLÓN SERVA FLORENCIA | D10: 19839679 | F10: VERDURA | G10: SOCIO
A11: 10 | B11: BALTAZAR AQUINO HEYDI | C11: =UPPER(B11) -> BALTAZAR AQUINO HEYDI | D11: 45247844 | F11: COMIDA | G11: SOCIO
A12: 11 | B12: Barzola Bernuy Ayra | C12: =UPPER(B12) -> BARZOLA BERNUY AYRA | D12: 20093891 | F12: TALLER | G12: SOCIO
A13: 12 | B13: Bastidas Ramírez Silvia Rosalía | C13: =UPPER(B13) -> BASTIDAS RAMÍREZ SILVIA ROSALÍA | D13: 20057738 | F13: CARNE | G13: SOCIO
... A25: 24 | B25: Cuicapusa Huarcaya Dorcas Isabel | C25: =UPPER(B25) -> CUICAPUSA HUARCAYA DORCAS ISABEL | D25: 20028017 | F25: TALLER | G25: SOCIO
A26: Nº | B26: APELLIDOS Y NOMBRES | C26: APELLIDOS Y NOMBRES | D26: DNI | E26: FIRMA
A27: 25 | B27: Cuicapusa Huarcaya Hilda | C27: =UPPER(B27) -> CUICAPUSA HUARCAYA HILDA | D27: 20052572 | F27: COMIDA | G27: SOCIO
A28: 26 | B28: De La Cruz Pampas Silvia Herlinda | C28: =UPPER(B28) -> DE LA CRUZ PAMPAS SILVIA HERLINDA | D28: 20405583 | F28: PAPA | G28: SOCIO
A29: 27 | B29: Esteban Llacsa Clemencia Ana | C29: =UPPER(B29) -> ESTEBAN LLACSA CLEMENCIA ANA | D29: 19836345 | F29: ABARROTES | G29: SOCIO
A30: 28 | B30: Flores Villaverde Gloria Adela | C30: =UPPER(B30) -> FLORES VILLAVERDE GLORIA ADELA | D30: 19995621 | F30: MERCERIA | G30: SOCIO
A31: 29 | B31: Galván Vílchez Luz Rebeca | C31: =UPPER(B31) -> GALVÁN VÍLCHEZ LUZ REBECA | D31: 20097664 | F31: CARNE | G31: SOCIO
A32: 30 | B32: Gamarra Ramos Carmen Mercedes | C32: =UPPER(B32) -> GAMARRA RAMOS CARMEN MERCEDES | D32: 19891347 | F32: MERCERIA | G32: SOCIO
A33: 31 | B33: Garcia Acuña Doris | C33: =UPPER(B33) -> GARCIA ACUÑA DORIS | D33: 21271301 | F33: ABARROTES | G33: SOCIO
A34: 32 | B34: Garcia Acuña, MargaRITA | C34: =UPPER(B34) -> GARCIA ACUÑA, MARGARITA | D34: 21270275 | F34: ABARROTES | G34: SOCIO
A35: 33 | B35: García Coca Freddy Emerson | C35: =UPPER(B35) -> GARCÍA COCA FREDDY EMERSON | D35: 20122038 | F35: LIBRERÍA | G35: SOCIO
A36: 34 | B36: Gómez Romero Julia | C36: =UPPER(B36) -> GÓMEZ ROMERO JULIA | D36: 80151899 | F36: TALLER | G36: SOCIO
A37: 35 | B37: Gongora Quispe Domola | C37: =UPPER(B37) -> GONGORA QUISPE DOMOLA | D37: 19863262 | F37: ABARROTES | G37: SOCIO
A38: 36 | B38: Gutiérrez Viuda De Mendoza Rayda Alejandra | C38: =UPPER(B38) -> GUTIÉRREZ VIUDA DE MENDOZA RAYDA ALEJANDRA | D38: 19802754 | F38: CONDIMENTO | G38: SOCIO
... A50: 48 | B50: Luis Gallardo Eloy Mariano | C50: =UPPER(B50) -> LUIS GALLARDO ELOY MARIANO | D50: 20087969 | F50: TALLER | G50: SOCIO
A51: Nº | B51: APELLIDOS Y NOMBRES | C51: APELLIDOS Y NOMBRES | D51: DNI | E51: FIRMA
A52: 49 | B52: Luis Marticorena Aussy Gardenia | C52: =UPPER(B52) -> LUIS MARTICORENA AUSSY GARDENIA | D52: 20073695 | F52: MERCERIA | G52: SOCIO
A53: 50 | B53: Marcelo de Cortez Udalia | C53: =UPPER(B53) -> MARCELO DE CORTEZ UDALIA | D53: 19993410 | F53: COMIDA | G53: SOCIO
A54: 51 | B54: Marticorena Benavente Yohana Mercedes | C54: =UPPER(B54) -> MARTICORENA BENAVENTE YOHANA MERCEDES | D54: 20670271 | F54: CARNE | G54: SOCIO
A55: 52 | B55: MATOS MONDARGO JOSE CARLOS | C55: =UPPER(B55) -> MATOS MONDARGO JOSE CARLOS | D55: 48407208 | F55: ABARROTES | G55: SOCIO
A56: 53 | B56: Matos Villazana Sonia | C56: =UPPER(B56) -> MATOS VILLAZANA SONIA | D56: 20042885 | F56: ABARROTES | G56: SOCIO
A57: 54 | B57: Medina Orihuela Gabriela Jhoselin | C57: =UPPER(B57) -> MEDINA ORIHUELA GABRIELA JHOSELIN | D57: 70041842 | F57: JUGOS | G57: SOCIO
A58: 55 | B58: Mendoza Asto Ayda | C58: =UPPER(B58) -> MENDOZA ASTO AYDA | D58: 20047549 | F58: CARNE | G58: SOCIO
A59: 56 | B59: MENDOZA ASTO CARMEN KARINA | C59: =UPPER(B59) -> MENDOZA ASTO CARMEN KARINA | D59: 40061246 | F59: ABARROTES | G59: SOCIO
A60: 57 | C60: MENDOZA BENDEZU MARISOL MAKRINA | D60: 40078108 | F60: VERDURA | G60: SOCIO
A61: 58 | B61: Meza Schwartz Galina Vicenta | C61: =UPPER(B61) -> MEZA SCHWARTZ GALINA VICENTA | D61: 20040608 | F61: CARNE | G61: SOCIO
A62: 59 | B62: Molina De Gaspar Teodosia | C62: =UPPER(B62) -> MOLINA DE GASPAR TEODOSIA | D62: 19881249 | F62: VERDURA | G62: SOCIO
...
